Workbook

Sheet Recap
B1: EUR / EUR Hedgé | E1: The longer the better
A4: Asset Class | B4: Actions | F4: Souverain | H4: Credit HY | J4: Crédit IG | M4: Private Equity | N4: Real Assets | O4: Gold | P4: Diversification
A5: Geo | B5: US | C5: EU | D5: JA | E5: EM | F5: US | G5: EU | H5: US | I5: EU | J5: US | K5: EU | L5: EM | M5: Global/US | P5: World
A6: Underlying | B6: S&P500 | C6: Eurostoxx 50 | D6: Nikkei 225 | E6: MSCI Emerging Markets | F6: SPDR Barclays Cap US Treasury Bond | G6: Bloomberg Euro Treasury 7-10 Year Bond Index | H6: Indice Markit iBoxx USD Liquid High Yield | I6: Fidelity European Hi Yi Fd A Eur Cap | J6: iShares 1-5 Year Investment Grade Corporate Bond ETF | K6: EUR Corporate Bond | L6: Global Emerging Markets Bond | M6: / | O6: Gold Bullion Securities | P6: FE Amundi International AE
A7: EOD (Y/N) | B7: Y | C7: Y | D7: Y | E7: Y | F7: Y | G7: Y | H7: Y | I7: Y | J7: Y | K7: Y | L7: Y | M7: Y
A8: Ticker | B8: CSSPX.MI | C8: C50.PA | D8: DBXJ.XETRA | E8: LEM.PA | F8: TSYE.PA | G8: MTD.PA | H8: HYG.US | I8: LU0562246453.EUFUND | J8: IGSB.US | K8: IE00B67T5G21.EUFUND | L8: LU0562246453.EUFUND | M8: NBPVF.US | N8: IEIF OPCI GRAND PUBLIC MENSUEL | O8: GBS.MI | P8: LU0565135745.EUFUND
A9: Currency | B9: EUR | C9: USD | D9: EUR | E9: EUR | F9: EUR | G9: EUR | H9: USD | I9: EUR | J9: USD | K9: EUR | M9: USD
A10: Start Date | B10: 40317 | C10: 37514 | D10: 39083 | E10: 39190 | F10: 39478 | G10: 41184 | H10: 39176 | I10: 39652 | J10: 39083 | K10: 40948 | L10: 40858 | M10: 39983 | N10: 39814 | O10: 39814 | P10: 40515
A11: End Date
A12: Freq | B12: Daily | C12: Daily | D12: Daily | E12: Daily | F12: Daily | G12: Daily | H12: Daily | I12: Daily | J12: Daily | K12: Daily | L12: Daily | M12: Twice a month | N12: Twice a month | O12: Daily | P12: Daily
A14: J'ai supprimé la colonne sur le fonds Immo

Sheet raw_data
A1: dates | B1: CSSPX.MI | D1: dates | E1: C50.PA | G1: dates | H1: DBXJ.XETRA | J1: dates | K1: LEM.PA | M1: dates | N1: TSYE.PA | P1: dates | Q1: MTD.PA | S1: dates | T1: HYG.US | V1: dates | W1: LU0251130802.EUFUND | Y1: dates | Z1: IGSB.US | AB1: dates | AC1: IE00B67T5G21.EUFUND | AE1: dates | AF1: LU0562246453.EUFUND | AH1: dates | AI1: NBPVF.US | AK1: dates | AL1: IEIF OPCI GRAND PUBLIC MENSUEL | AN1: dates | AO1: GBS.MI | AQ1: dates | AR1: EURUSD.FOREX | AT1: dates | AU1: LU0565135745.EUFUND
A2: {=_xll.EndOfDayHistory(B1,"01/01/2009","31/03/2024")} -> 40325 | B2: 75.52 | D2: {=_xll.EndOfDayHistory(E1,"01/01/2009","31/03/2024")} -> 39819 | E2: 39.465 | G2: {=_xll.EndOfDayHistory(H1,"01/01/2009","31/03/2024")} -> 39815 | H2: 25 | J2: {=_xll.EndOfDayHistory(K1,"01/01/2009","31/03/2024")} -> 39815 | K2: 4.0587 | M2: {=_xll.EndOfDayHistory(N1,"01/01/2009","31/03/2024")} -> 41116 | N2: 75.0707 | P2: {=_xll.EndOfDayHistory(Q1,"01/01/2009","31/03/2024")} -> 39815 | Q2: 113.23 | S2: {=_xll.EndOfDayHistory(T1,"01/01/2009","31/03/2024")} -> 39815 | T2: 29.7351 | V2: {=_xll.EndOfDayHistory(W1,"01/01/2009","31/03/2024")} -> 39815 | W2: 6.978 | Y2: {=_xll.EndOfDayHistory(Z1,"01/01/2009","31/03/2024")} -> 39815 | Z2: 36.3942 | AB2: {=_xll.EndOfDayHistory(AC1,"01/01/2009","31/03/2024")} -> 40948 | AC2: 10 | AE2: {=_xll.EndOfDayHistory(AF1,"01/01/2009","31/03/2024")} -> 40858 | AF2: 100 | AH2: {=_xll.EndOfDayHistory(AI1,"01/01/2009","31/03/2024")} -> 39983 | AI2: 3.2477 | AK2: 39629 | AL2: 1000 | AN2: {=_xll.EndOfDayHistory(AO1,"01/01/2009","31/03/2024")} -> 39815 | AO2: 61.99 | AQ2: {=_xll.EndOfDayHistory(AR1,"01/01/2009","31/03/2024")} -> 39814 | AR2: 1.399 | AT2: {=_xll.EndOfDayHistory(AU1,"01/01/2009","31/03/2024")} -> 40515 | AU2: 100.48
A3: 40329 | B3: 75.84 | D3: 39825 | E3: 37.955 | G3: 39818 | H3: 24.95 | J3: 39818 | K3: 4.2683 | M3: 41129 | N3: 73.4404 | P3: 39818 | Q3: 113.1 | S3: 39818 | T3: 31.1715 | V3: 39818 | W3: 6.966 | Y3: 39818 | Z3: 36.1991 | AB3: 40949 | AC3: 10.016 | AE3: 40861 | AF3: 100.04 | AH3: 40018 | AI3: 2.5154 | AK3: 39660 | AL3: 995.96427 | AN3: 39818 | AO3: 61.36 | AQ3: 39815 | AR3: 1.3879 | AT3: 40518 | AU3: 99.73
A4: 40330 | B4: 75.49 | D4: 39828 | E4: 34.435 | G4: 39819 | H4: 25.16 | J4: 39819 | K4: 4.4398 | M4: 41157 | N4: 72.3875 | P4: 39819 | Q4: 111.88 | S4: 39819 | T4: 31.4344 | V4: 39819 | W4: 7.004 | Y4: 39819 | Z4: 36.7193 | AB4: 40952 | AC4: 10.0213 | AE4: 40862 | AF4: 99.71 | AH4: 40021 | AI4: 2.5472 | AK4: 39691 | AL4: 993.22602 | AN4: 39819 | AO4: 61.92 | AQ4: 39818 | AR4: 1.3605 | AT4: 40519 | AU4: 100.42
A5: 40333 | B5: 76.73 | D5: 39832 | E5: 34.41 | G5: 39820 | H5: 24.44 | J5: 39820 | K5: 4.2111 | M5: 41169 | N5: 68.8382 | P5: 39820 | Q5: 111.83 | S5: 39820 | T5: 30.8669 | V5: 39820 | W5: 7.062 | Y5: 39820 | Z5: 36.7085 | AB5: 40953 | AC5: 10.018 | AE5: 40863 | AF5: 99.35 | AH5: 40022 | AI5: 2.5472 | AK5: 39721 | AL5: 992.27989 | AN5: 39820 | AO5: 60.92 | AQ5: 39819 | AR5: 1.351 | AT5: 40520 | AU5: 99.91
A6: 40337 | B6: 75.11 | D6: 39833 | E6: 33.775 | G6: 39821 | H6: 24.4 | J6: 39821 | K6: 4.0206 | M6: 41179 | N6: 70.9185 | P6: 39821 | Q6: 112.42 | S6: 39821 | T6: 30.418 | V6: 39821 | W6: 7.186 | Y6: 39821 | Z6: 36.7807 | AB6: 40954 | AC6: 10.0369 | AE6: 40864 | AF6: 99.21 | AH6: 40023 | AI6: 2.5472 | AK6: 39752 | AL6: 990.12911 | AN6: 39821 | AO6: 61.56 | AQ6: 39820 | AR6: 1.3634 | AT6: 40521 | AU6: 100.56
A7: 40338 | B7: 74.81 | D7: 39834 | E7: 33.765 | G7: 39822 | H7: 24.61 | J7: 39822 | K7: 4.0492 | M7: 41222 | N7: 71.8186 | P7: 39822 | Q7: 112.74 | S7: 39822 | T7: 30.8653 | V7: 39822 | W7: 7.243 | Y7: 39822 | Z7: 36.9036 | AB7: 40955 | AC7: 10.0077 | AE7: 40865 | AF7: 99.37 | AH7: 40049 | AI7: 2.8338 | AK7: 39782 | AL7: 988.65492 | AN7: 39822 | AO7: 62.65 | AQ7: 39821 | AR7: 1.3727 | AT7: 40522 | AU7: 101.05
A8: 40343 | B8: 76.39 | D8: 39835 | E8: 32.89 | G8: 39825 | H8: 24.64 | J8: 39825 | K8: 3.9539 | M8: 41246 | N8: 69.8826 | P8: 39825 | Q8: 113.05 | S8: 39825 | T8: 30.1943 | V8: 39825 | W8: 7.303 | Y8: 39825 | Z8: 36.5495 | AB8: 40956 | AC8: 10.011 | AE8: 40868 | AF8: 98.86 | AH8: 40058 | AI8: 2.751 | AK8: 39813 | AL8: 987.3137 | AN8: 39825 | AO8: 60.9 | AQ8: 39822 | AR8: 1.344 | AT8: 40525 | AU8: 100.81
A9: 40344 | B9: 76.34 | D9: 39836 | E9: 32.695 | G9: 39826 | H9: 24.34 | J9: 39826 | K9: 4.0111 | M9: 41250 | N9: 70.5534 | P9: 39826 | Q9: 112.89 | S9: 39826 | T9: 30.0837 | V9: 39826 | W9: 7.346 | Y9: 39826 | Z9: 36.806 | AB9: 40959 | AC9: 10.016 | AE9: 40869 | AF9: 98.72 | AH9: 40084 | AI9: 3.5024 | AK9: 39844 | AL9: 987.91684 | AN9: 39826 | AO9: 61.36 | AQ9: 39825 | AR9: 1.3371 | AT9: 40526 | AU9: 100.26
A10: 40345 | B10: 76.61 | D10: 39841 | E10: 35.225 | G10: 39827 | H10: 23.83 | J10: 39827 | K10: 3.811 | M10: 41254 | N10: 70.2562 | P10: 39827 | Q10: 113.24 | S10: 39827 | T10: 29.6998 | V10: 39827 | W10: 7.36 | Y10: 39827 | Z10: 36.5279 | AB10: 40960 | AC10: 10.026 | AE10: 40870 | AF10: 98.6 | AH10: 40087 | AI10: 3.4076 | AK10: 39872 | AL10: 988.82345 | AN10: 39827 | AO10: 60.79 | AQ10: 39826 | AR10: 1.3196 | AT10: 40527 | AU10: 100.71
A11: 40347 | B11: 76.6 | D11: 39848 | E11: 35.155 | G11: 39828 | H11: 24.09 | J11: 39828 | K11: 3.7538 | M11: 41487 | N11: 66.1635 | P11: 39828 | Q11: 113.1 | S11: 39828 | T11: 29.5821 | V11: 39828 | W11: 7.366 | Y11: 39828 | Z11: 36.676 | AB11: 40961 | AC11: 10.041 | AE11: 40871 | AF11: 98.57 | AH11: 40109 | AI11: 3.0248 | AK11: 39903 | AL11: 996.21904 | AN11: 39828 | AO11: 60.74 | AQ11: 39827 | AR11: 1.3162 | AT11: 40528 | AU11: 100.7
A12: 40353 | B12: 74.92 | D12: 39855 | E12: 34.565 | G12: 39829 | H12: 24.05 | J12: 39829 | K12: 3.8014 | M12: 41526 | N12: 65.5946 | P12: 39829 | Q12: 112.97 | S12: 39829 | T12: 29.8215 | V12: 39829 | W12: 7.493 | Y12: 39829 | Z12: 36.8602 | AB12: 40962 | AC12: 10.058 | AE12: 40872 | AF12: 98.28 | AH12: 40114 | AI12: 3.1461 | AK12: 39933 | AL12: 1012.4533 | AN12: 39829 | AO12: 62.08 | AQ12: 39828 | AR12: 1.3154 | AT12: 40529 | AU12: 101.45
A13: 40354 | B13: 74.05 | D13: 39860 | E13: 33.57 | G13: 39832 | H13: 23.92 | J13: 39832 | K13: 3.7919 | M13: 41528 | N13: 65.1615 | P13: 39832 | Q13: 112.09 | S13: 39833 | T13: 29.3113 | V13: 39832 | W13: 7.526 | Y13: 39833 | Z13: 36.7771 | AB13: 40963 | AC13: 10.075 | AE13: 40875 | AF13: 98.35 | AH13: 40136 | AI13: 3.1203 | AK13: 39964 | AL13: 1017.6036 | AN13: 39832 | AO13: 62.48 | AQ13: 39829 | AR13: 1.3304 | AT13: 40532 | AU13: 101.75
A14: 40358 | B14: 73.08 | D14: 39867 | E14: 31.18 | G14: 39833 | H14: 24 | J14: 39833 | K14: 3.7443 | M14: 41529 | N14: 65.3313 | P14: 39833 | Q14: 111.86 | S14: 39834 | T14: 29.3152 | V14: 39833 | W14: 7.388 | Y14: 39834 | Z14: 36.7916 | AB14: 40966 | AC14: 10.105 | AE14: 40876 | AF14: 98.36 | AH14: 40144 | AI14: 3.1203 | AK14: 39994 | AL14: 1012.6128 | AN14: 39833 | AO14: 65.67 | AQ14: 39832 | AR14: 1.3112 | AT14: 40533 | AU14: 102.21
... A191: 40717 | B191: 77.11 | D191: 40130 | E191: 45.775 | G191: 40085 | H191: 24.65 | J191: 40085 | K191: 6.0657 | M191: 42240 | N191: 79.8844 | P191: 40091 | Q191: 118.6 | S191: 40088 | T191: 35.6089 | V191: 40080 | W191: 11 | Y191: 40088 | Z191: 38.6535 | AB191: 41227 | AC191: 10.877 | AE191: 41128 | AF191: 110.51 | AH191: 42613 | AI191: 7.4631 | AK191: 45382 | AL191: 1573.7451 | AN191: 40086 | AO191: 66.9 | AQ191: 40079 | AR191: 1.4731 | AT191: 40791 | AU191: 93.68
A192: 40718 | B192: 77.87 | D192: 40133 | E192: 46.395 | G192: 40086 | H192: 24.6 | J192: 40086 | K192: 6.0464 | M192: 42241 | N192: 80.8366 | P192: 40092 | Q192: 118.41 | S192: 40091 | T192: 36.0869 | V192: 40081 | W192: 11.04 | Y192: 40091 | Z192: 38.6796 | AB192: 41228 | AC192: 10.877 | AE192: 41129 | AF192: 110.42 | AH192: 42614 | AI192: 7.8199 | AN192: 40087 | AO192: 67.49 | AQ192: 40080 | AR192: 1.4661 | AT192: 40792 | AU192: 93.38
A193: 40721 | B193: 77.23 | D193: 40134 | E193: 46.13 | G193: 40087 | H193: 24.49 | J193: 40087 | K193: 5.9838 | M193: 42243 | N193: 81.7023 | P193: 40093 | Q193: 118.81 | S193: 40092 | T193: 35.9632 | V193: 40084 | W193: 11.04 | Y193: 40092 | Z193: 38.6684 | AB193: 41229 | AC193: 10.88 | AE193: 41130 | AF193: 110.27 | AH193: 42615 | AI193: 7.8199 | AN193: 40088 | AO193: 67.18 | AQ193: 40081 | AR193: 1.4688 | AT193: 40793 | AU193: 93.02
A194: 40722 | B194: 77.29 | D194: 40135 | E194: 46.145 | G194: 40088 | H194: 23.72 | J194: 40088 | K194: 5.8778 | M194: 42247 | N194: 82.0486 | P194: 40094 | Q194: 118.9 | S194: 40093 | T194: 36.2278 | V194: 40085 | W194: 11.07 | Y194: 40093 | Z194: 38.6796 | AB194: 41232 | AC194: 10.873 | AE194: 41131 | AF194: 110.02 | AH194: 42619 | AI194: 7.7907 | AN194: 40091 | AO194: 67.16 | AQ194: 40084 | AR194: 1.4621 | AT194: 40794 | AU194: 94.54
A195: 40723 | B195: 78.13 | D195: 40136 | E195: 45.345 | G195: 40091 | H195: 23.85 | J195: 40091 | K195: 5.9934 | M195: 42263 | N195: 80.9059 | P195: 40095 | Q195: 118.45 | S195: 40094 | T195: 36.4583 | V195: 40086 | W195: 11.1 | Y195: 40094 | Z195: 38.687 | AB195: 41233 | AC195: 10.856 | AE195: 41134 | AF195: 110.11 | AH195: 42620 | AI195: 7.8271 | AN195: 40092 | AO195: 69.06 | AQ195: 40085 | AR195: 1.4585 | AT195: 40795 | AU195: 94.66
A196: 40724 | B196: 78.37 | D196: 40137 | E196: 44.93 | G196: 40092 | H196: 24.08 | J196: 40092 | K196: 6.1476 | M196: 42264 | N196: 80.8193 | P196: 40098 | Q196: 118.43 | S196: 40095 | T196: 36.5992 | V196: 40087 | W196: 11.13 | Y196: 40095 | Z196: 38.6126 | AB196: 41234 | AC196: 10.854 | AE196: 41135 | AF196: 109.95 | AH196: 42621 | AI196: 7.8635 | AN196: 40093 | AO196: 69.51 | AQ196: 40086 | AR196: 1.4636 | AT196: 40798 | AU196: 94.6
A197: 40725 | B197: 78.48 | D197: 40140 | E197: 45.97 | G197: 40093 | H197: 24.26 | J197: 40093 | K197: 6.109 | M197: 42265 | N197: 80.9924 | P197: 40099 | Q197: 118.44 | S197: 40098 | T197: 36.5906 | V197: 40088 | W197: 11.13 | Y197: 40098 | Z197: 38.6424 | AB197: 41235 | AC197: 10.862 | AE197: 41136 | AF197: 109.57 | AH197: 42622 | AI197: 7.9364 | AN197: 40094 | AO197: 69.71 | AQ197: 40087 | AR197: 1.4533 | AT197: 40799 | AU197: 94.72
A198: 40728 | B198: 79.28 | D198: 40141 | E198: 45.64 | G198: 40094 | H198: 24.55 | J198: 40094 | K198: 6.1909 | M198: 42269 | N198: 82.6718 | P198: 40100 | Q198: 118.01 | S198: 40099 | T198: 36.5821 | V198: 40091 | W198: 11.32 | Y198: 40099 | Z198: 38.6721 | AB198: 41236 | AC198: 10.864 | AE198: 41137 | AF198: 109.3 | AH198: 42625 | AI198: 7.7907 | AN198: 40095 | AO198: 69.7 | AQ198: 40088 | AR198: 1.4572 | AT198: 40800 | AU198: 95.1
A199: 40729 | B199: 79.6 | D199: 40142 | E199: 46.02 | G199: 40095 | H199: 24.45 | J199: 40095 | K199: 6.2247 | M199: 42271 | N199: 81.988 | P199: 40101 | Q199: 117.47 | S199: 40100 | T199: 36.7272 | V199: 40092 | W199: 11.34 | Y199: 40100 | Z199: 38.7094 | AB199: 41239 | AC199: 10.878 | AE199: 41138 | AF199: 109.21 | AH199: 42626 | AI199: 7.7543 | AN199: 40098 | AO199: 69.87 | AQ199: 40091 | AR199: 1.465 | AT199: 40801 | AU199: 95.56
A200: 40730 | B200: 80.46 | D200: 40143 | E200: 44.405 | G200: 40098 | H200: 24.7 | J200: 40098 | K200: 6.2536 | M200: 42272 | N200: 82.213 | P200: 40102 | Q200: 117.71 | S200: 40101 | T200: 36.7187 | V200: 40093 | W200: 11.38 | Y200: 40101 | Z200: 38.6833 | AB200: 41240 | AC200: 10.873 | AE200: 41141 | AF200: 109.21 | AH200: 42627 | AI200: 7.9 | AN200: 40099 | AO200: 69.99 | AQ200: 40092 | AR200: 1.4718 | AT200: 40802 | AU200: 95.15
A201: 40731 | B201: 81.39 | D201: 40144 | E201: 44.875 | G201: 40099 | H201: 24.33 | J201: 40099 | K201: 6.2102 | M201: 42275 | N201: 82.2477 | P201: 40105 | Q201: 117.7 | S201: 40102 | T201: 36.7144 | V201: 40094 | W201: 11.18 | Y201: 40102 | Z201: 38.6908 | AB201: 41241 | AC201: 10.895 | AE201: 41142 | AF201: 109.39 | AH201: 42628 | AI201: 7.9072 | AN201: 40100 | AO201: 69.7 | AQ201: 40093 | AR201: 1.4688 | AT201: 40805 | AU201: 96.11
A202: 40732 | B202: 81.81 | D202: 40147 | E202: 44.39 | G202: 40100 | H202: 24.46 | J202: 40100 | K202: 6.3403 | M202: 42276 | N202: 82.3169 | P202: 40106 | Q202: 118.37 | S202: 40105 | T202: 36.723 | V202: 40095 | W202: 11.43 | Y202: 40105 | Z202: 38.7168 | AB202: 41242 | AC202: 10.892 | AE202: 41143 | AF202: 109.6 | AH202: 42629 | AI202: 8.082 | AN202: 40101 | AO202: 69.3 | AQ202: 40094 | AR202: 1.479 | AT202: 40806 | AU202: 96.8
A203: 40735 | B203: 81.56 | D203: 40148 | E203: 45.58 | G203: 40101 | H203: 24.16 | J203: 40101 | K203: 6.321 | M203: 42277 | N203: 82.9142 | P203: 40107 | Q203: 117.78 | S203: 40106 | T203: 36.7913 | V203: 40098 | W203: 11.23 | Y203: 40106 | Z203: 38.7466 | AB203: 41243 | AC203: 10.892 | AE203: 41144 | AF203: 109.95 | AH203: 42633 | AI203: 8.3368 | AN203: 40102 | AO203: 69.33 | AQ203: 40095 | AR203: 1.473 | AT203: 40807 | AU203: 96.33
... A781: 41568 | B781: 114.14 | D781: 40977 | E781: 43.145 | G781: 40927 | H781: 27.52 | J781: 40927 | K781: 7.66 | M781: 43616 | N781: 88.8237 | P781: 40984 | Q781: 125.05 | S781: 40945 | T781: 46.7358 | V781: 40912 | W781: 12.99 | Y781: 40945 | Z781: 41.0206 | AB781: 42093 | AC781: 12.35 | AE781: 41977 | AF781: 116.12 | AH781: 45379 | AI781: 20.5 | AN781: 40931 | AO781: 124.83 | AQ781: 40905 | AR781: 1.2936 | AT781: 41649 | AU781: 119.04
A782: 41569 | B782: 113.75 | D782: 40980 | E782: 43.13 | G782: 40928 | H782: 27.75 | J782: 40928 | K782: 7.618 | M782: 43619 | N782: 88.6506 | P782: 40987 | Q782: 125.22 | S782: 40946 | T782: 46.8285 | V782: 40913 | W782: 12.98 | Y782: 40946 | Z782: 41.1462 | AB782: 42094 | AC782: 12.361 | AE782: 41978 | AF782: 115.97 | AN782: 40932 | AO782: 124.48 | AQ782: 40906 | AR782: 1.2962 | AT782: 41652 | AU782: 119.05
A783: 41570 | B783: 113.57 | D783: 40981 | E783: 43.835 | G783: 40931 | H783: 27.77 | J783: 40931 | K783: 7.663 | M783: 43620 | N783: 88.3136 | P783: 40988 | Q783: 124.81 | S783: 40947 | T783: 46.8697 | V783: 40914 | W783: 12.99 | Y783: 40947 | Z783: 41.1761 | AB783: 42095 | AC783: 12.366 | AE783: 41981 | AF783: 115.61 | AN783: 40933 | AO783: 123.97 | AQ783: 40907 | AR783: 1.2948 | AT783: 41653 | AU783: 118.78
A784: 41571 | B784: 113.72 | D784: 40982 | E784: 44.12 | G784: 40932 | H784: 27.56 | J784: 40932 | K784: 7.66 | M784: 43622 | N784: 88.0828 | P784: 40989 | Q784: 124.65 | S784: 40948 | T784: 46.8903 | V784: 40917 | W784: 12.99 | Y784: 40948 | Z784: 41.1502 | AB784: 42096 | AC784: 12.363 | AE784: 41982 | AF784: 115.24 | AN784: 40934 | AO784: 127.05 | AQ784: 40910 | AR784: 1.2929 | AT784: 41654 | AU784: 120.22
A785: 41572 | B785: 113.97 | D785: 40983 | E785: 44.505 | G785: 40933 | H785: 27.68 | J785: 40933 | K785: 7.645 | M785: 43623 | N785: 87.9409 | P785: 40990 | Q785: 124.67 | S785: 40949 | T785: 46.4834 | V785: 40918 | W785: 13.01 | Y785: 40949 | Z785: 41.1305 | AB785: 42101 | AC785: 12.374 | AE785: 41983 | AF785: 114.61 | AN785: 40935 | AO785: 127.57 | AQ785: 40911 | AR785: 1.3051 | AT785: 41655 | AU785: 120.13
A786: 41575 | B786: 114.54 | D786: 40984 | E786: 44.72 | G786: 40934 | H786: 27.64 | J786: 40934 | K786: 7.713 | M786: 43626 | N786: 87.7586 | P786: 40991 | Q786: 124.88 | S786: 40952 | T786: 46.6173 | V786: 40919 | W786: 13.03 | Y786: 40952 | Z786: 41.1659 | AB786: 42102 | AC786: 12.39 | AE786: 41984 | AF786: 114.63 | AN786: 40938 | AO786: 128.13 | AQ786: 40912 | AR786: 1.2942 | AT786: 41656 | AU786: 120.54
A787: 41576 | B787: 115.26 | D787: 40987 | E787: 44.755 | G787: 40935 | H787: 27.6 | J787: 40935 | K787: 7.656 | M787: 43629 | N787: 88.2614 | P787: 40994 | Q787: 124.88 | S787: 40953 | T787: 46.6173 | V787: 40920 | W787: 13.06 | Y787: 40953 | Z787: 41.1737 | AB787: 42103 | AC787: 12.392 | AE787: 41985 | AF787: 114.2 | AN787: 40939 | AO787: 128.53 | AQ787: 40913 | AR787: 1.278 | AT787: 41659 | AU787: 120.51
A788: 41577 | B788: 115.04 | D788: 40988 | E788: 44.18 | G788: 40938 | H788: 27.64 | J788: 40938 | K788: 7.568 | M788: 43630 | N788: 88.7614 | P788: 40995 | Q788: 124.71 | S788: 40954 | T788: 46.468 | V788: 40921 | W788: 13.09 | Y788: 40954 | Z788: 41.1816 | AB788: 42104 | AC788: 12.393 | AE788: 41988 | AF788: 113.61 | AN788: 40940 | AO788: 128.4 | AQ788: 40914 | AR788: 1.2721 | AT788: 41660 | AU788: 120.67
A789: 41578 | B789: 116.27 | D789: 40989 | E789: 44.035 | G789: 40939 | H789: 27.72 | J789: 40939 | K789: 7.644 | M789: 43633 | N789: 88.6918 | P789: 40996 | Q789: 124.95 | S789: 40955 | T789: 46.6637 | V789: 40924 | W789: 13.1 | Y789: 40955 | Z789: 41.2012 | AB789: 42107 | AC789: 12.4 | AE789: 41989 | AF789: 112.03 | AN789: 40941 | AO789: 129.43 | AQ789: 40917 | AR789: 1.2767 | AT789: 41661 | AU789: 120.44
A790: 41579 | B790: 116.64 | D790: 40990 | E790: 43.405 | G790: 40940 | H790: 27.8 | J790: 40940 | K790: 7.752 | M790: 43634 | N790: 89.1909 | P790: 40997 | Q790: 124.59 | S790: 40956 | T790: 46.6482 | V790: 40925 | W790: 13.15 | Y790: 40956 | Z790: 41.1737 | AB790: 42108 | AC790: 12.403 | AE790: 41990 | AF790: 112.38 | AN790: 40942 | AO790: 128.91 | AQ790: 40918 | AR790: 1.2772 | AT790: 41662 | AU790: 119.1
A791: 41582 | B791: 116.85 | D791: 40991 | E791: 43.28 | G791: 40941 | H791: 27.9 | J791: 40941 | K791: 7.856 | M791: 43636 | N791: 88.9024 | P791: 40998 | Q791: 125.1 | S791: 40960 | T791: 46.8234 | V791: 40926 | W791: 13.17 | Y791: 40960 | Z791: 41.1973 | AB791: 42109 | AC791: 12.414 | AE791: 41991 | AF791: 114.13 | AN791: 40945 | AO791: 127.27 | AQ791: 40919 | AR791: 1.2704 | AT791: 41663 | AU791: 117.94
A792: 41583 | B792: 117.23 | D792: 40994 | E792: 43.525 | G792: 40942 | H792: 28.09 | J792: 40942 | K792: 7.953 | M792: 43637 | N792: 88.1149 | P792: 41001 | Q792: 125.45 | S792: 40961 | T792: 46.9727 | V792: 40927 | W792: 13.19 | Y792: 40961 | Z792: 41.2719 | AB792: 42110 | AC792: 12.408 | AE792: 41992 | AF792: 114.35 | AN792: 40946 | AO792: 127.19 | AQ792: 40920 | AR792: 1.2826 | AT792: 41666 | AU792: 117.16
A793: 41584 | B793: 117.19 | D793: 40995 | E793: 43.315 | G793: 40945 | H793: 28.06 | J793: 40945 | K793: 7.912 | M793: 43640 | N793: 87.8127 | P793: 41002 | Q793: 124.99 | S793: 40962 | T793: 47.1427 | V793: 40928 | W793: 13.22 | Y793: 40962 | Z793: 41.268 | AB793: 42111 | AC793: 12.404 | AE793: 41995 | AF793: 114.97 | AN793: 40947 | AO793: 126.91 | AQ793: 40921 | AR793: 1.2677 | AT793: 41667 | AU793: 117.61
...

Sheet clean_data
A1: Dates | B1: CSSPX.MI | C1: C50.PA | D1: DBXJ.XETRA | E1: LEM.PA | F1: TSYE.PA | G1: MTD.PA | H1: HYG.US | I1: LU0251130802.EUFUND | J1: IGSB.US | K1: IE00B67T5G21.EUFUND | L1: LU0562246453.EUFUND | M1: NBPVF.US | N1: IEIF OPCI GRAND PUBLIC MENSUEL | O1: GBS.MI | P1: LU0565135745.EUFUND
A2: 41213 | B2: {=OFFSET(raw_data!$A$1,MATCH(clean_data!$A2,raw_data!A:A,1)-1,MATCH(clean_data!B$1,raw_data!$1:$1,0)-1,,)} -> 95.7 | C2: {=OFFSET(raw_data!$A$1,MATCH(clean_data!$A2,raw_data!D:D,1)-1,MATCH(clean_data!C$1,raw_data!$1:$1,0)-1,,)/INDEX(raw_data!$AR:$AR,MATCH(clean_data!A2,raw_data!$AQ:$AQ,1))} -> 34.35571 | D2: {=OFFSET(raw_data!$A$1,MATCH(clean_data!$A2,raw_data!G:G,1)-1,MATCH(clean_data!D$1,raw_data!$1:$1,0)-1,,)} -> 26.8 | E2: {=OFFSET(raw_data!$A$1,MATCH(clean_data!$A2,raw_data!J:J,1)-1,MATCH(clean_data!E$1,raw_data!$1:$1,0)-1,,)} -> 7.66 | F2: {=OFFSET(raw_data!$A$1,MATCH(clean_data!$A2,raw_data!M:M,1)-1,MATCH(clean_data!F$1,raw_data!$1:$1,0)-1,,)} -> 70.9185 | G2: {=OFFSET(raw_data!$A$1,MATCH(clean_data!$A2,raw_data!P:P,1)-1,MATCH(clean_data!G$1,raw_data!$1:$1,0)-1,,)} -> 132.29 | H2: {=OFFSET(raw_data!$A$1,MATCH(clean_data!$A2,raw_data!S:S,1)-1,MATCH(clean_data!H$1,raw_data!$1:$1,0)-1,,)} -> 49.9193 | I2: {=OFFSET(raw_data!$A$1,MATCH(clean_data!$A2,raw_data!V:V,1)-1,MATCH(clean_data!I$1,raw_data!$1:$1,0)-1,,)} -> 15.13 | J2: {=OFFSET(raw_data!$A$1,MATCH(clean_data!$A2,raw_data!Y:Y,1)-1,MATCH(clean_data!J$1,raw_data!$1:$1,0)-1,,)} -> 41.9921 | K2: {=OFFSET(raw_data!$A$1,MATCH(clean_data!$A2,raw_data!AB:AB,1)-1,MATCH(clean_data!K$1,raw_data!$1:$1,0)-1,,)} -> 10.801 | L2: {=OFFSET(raw_data!$A$1,MATCH(clean_data!$A2,raw_data!AE:AE,1)-1,MATCH(clean_data!L$1,raw_data!$1:$1,0)-1,,)} -> 112.31 | M2: {=OFFSET(raw_data!$A$1,MATCH(clean_data!$A2,raw_data!AH:AH,1)-1,MATCH(clean_data!M$1,raw_data!$1:$1,0)-1,,)} -> 4.8588 | N2: {=OFFSET(raw_data!$A$1,MATCH(clean_data!$A2,raw_data!AK:AK,1)-1,MATCH(clean_data!N$1,raw_data!$1:$1,0)-1,,)} -> 1308.3279 | O2: {=OFFSET(raw_data!$A$1,MATCH(clean_data!$A2,raw_data!AN:AN,1)-1,MATCH(clean_data!O$1,raw_data!$1:$1,0)-1,,)} -> 128.56 | P2: {=OFFSET(raw_data!$A$1,MATCH(clean_data!$A2,raw_data!AT:AT,1)-1,MATCH(clean_data!P$1,raw_data!$1:$1,0)-1,,)} -> 109.74
A3: =EOMONTH(A2,1) -> 41243 | B3: {=OFFSET(raw_data!$A$1,MATCH(clean_data!$A3,raw_data!A:A,1)-1,MATCH(clean_data!B$1,raw_data!$1:$1,0)-1,,)} -> 95.94 | C3: {=OFFSET(raw_data!$A$1,MATCH(clean_data!$A3,raw_data!D:D,1)-1,MATCH(clean_data!C$1,raw_data!$1:$1,0)-1,,)/INDEX(raw_data!$AR:$AR,MATCH(clean_data!A3,raw_data!$AQ:$AQ,1))} -> 35.338056 | D3: {=OFFSET(raw_data!$A$1,MATCH(clean_data!$A3,raw_data!G:G,1)-1,MATCH(clean_data!D$1,raw_data!$1:$1,0)-1,,)} -> 27.38 | E3: {=OFFSET(raw_data!$A$1,MATCH(clean_data!$A3,raw_data!J:J,1)-1,MATCH(clean_data!E$1,raw_data!$1:$1,0)-1,,)} -> 7.737 | F3: {=OFFSET(raw_data!$A$1,MATCH(clean_data!$A3,raw_data!M:M,1)-1,MATCH(clean_data!F$1,raw_data!$1:$1,0)-1,,)} -> 71.8186 | G3: {=OFFSET(raw_data!$A$1,MATCH(clean_data!$A3,raw_data!P:P,1)-1,MATCH(clean_data!G$1,raw_data!$1:$1,0)-1,,)} -> 134.78 | H3: {=OFFSET(raw_data!$A$1,MATCH(clean_data!$A3,raw_data!S:S,1)-1,MATCH(clean_data!H$1,raw_data!$1:$1,0)-1,,)} -> 50.4442 | I3: {=OFFSET(raw_data!$A$1,MATCH(clean_data!$A3,raw_data!V:V,1)-1,MATCH(clean_data!I$1,raw_data!$1:$1,0)-1,,)} -> 15.4 | J3: {=OFFSET(raw_data!$A$1,MATCH(clean_data!$A3,raw_data!Y:Y,1)-1,MATCH(clean_data!J$1,raw_data!$1:$1,0)-1,,)} -> 41.911 | K3: {=OFFSET(raw_data!$A$1,MATCH(clean_data!$A3,raw_data!AB:AB,1)-1,MATCH(clean_data!K$1,raw_data!$1:$1,0)-1,,)} -> 10.892 | L3: {=OFFSET(raw_data!$A$1,MATCH(clean_data!$A3,raw_data!AE:AE,1)-1,MATCH(clean_data!L$1,raw_data!$1:$1,0)-1,,)} -> 113.54 | M3: {=OFFSET(raw_data!$A$1,MATCH(clean_data!$A3,raw_data!AH:AH,1)-1,MATCH(clean_data!M$1,raw_data!$1:$1,0)-1,,)} -> 4.8588 | N3: {=OFFSET(raw_data!$A$1,MATCH(clean_data!$A3,raw_data!AK:AK,1)-1,MATCH(clean_data!N$1,raw_data!$1:$1,0)-1,,)} -> 1313.3428 | O3: {=OFFSET(raw_data!$A$1,MATCH(clean_data!$A3,raw_data!AN:AN,1)-1,MATCH(clean_data!O$1,raw_data!$1:$1,0)-1,,)} -> 127.4 | P3: {=OFFSET(raw_data!$A$1,MATCH(clean_data!$A3,raw_data!AT:AT,1)-1,MATCH(clean_data!P$1,raw_data!$1:$1,0)-1,,)} -> 109.7
A4: =EOMONTH(A3,1) -> 41274 | B4: {=OFFSET(raw_data!$A$1,MATCH(clean_data!$A4,raw_data!A:A,1)-1,MATCH(clean_data!B$1,raw_data!$1:$1,0)-1,,)} -> 94.41 | C4: {=OFFSET(raw_data!$A$1,MATCH(clean_data!$A4,raw_data!D:D,1)-1,MATCH(clean_data!C$1,raw_data!$1:$1,0)-1,,)/INDEX(raw_data!$AR:$AR,MATCH(clean_data!A4,raw_data!$AQ:$AQ,1))} -> 35.389512 | D4: {=OFFSET(raw_data!$A$1,MATCH(clean_data!$A4,raw_data!G:G,1)-1,MATCH(clean_data!D$1,raw_data!$1:$1,0)-1,,)} -> 28.43 | E4: {=OFFSET(raw_data!$A$1,MATCH(clean_data!$A4,raw_data!J:J,1)-1,MATCH(clean_data!E$1,raw_data!$1:$1,0)-1,,)} -> 8.022 | F4: {=OFFSET(raw_data!$A$1,MATCH(clean_data!$A4,raw_data!M:M,1)-1,MATCH(clean_data!F$1,raw_data!$1:$1,0)-1,,)} -> 70.2562 | G4: {=OFFSET(raw_data!$A$1,MATCH(clean_data!$A4,raw_data!P:P,1)-1,MATCH(clean_data!G$1,raw_data!$1:$1,0)-1,,)} -> 135.52 | H4: {=OFFSET(raw_data!$A$1,MATCH(clean_data!$A4,raw_data!S:S,1)-1,MATCH(clean_data!H$1,raw_data!$1:$1,0)-1,,)} -> 51.1511 | I4: {=OFFSET(raw_data!$A$1,MATCH(clean_data!$A4,raw_data!V:V,1)-1,MATCH(clean_data!I$1,raw_data!$1:$1,0)-1,,)} -> 15.8 | J4: {=OFFSET(raw_data!$A$1,MATCH(clean_data!$A4,raw_data!Y:Y,1)-1,MATCH(clean_data!J$1,raw_data!$1:$1,0)-1,,)} -> 42.0173 | K4: {=OFFSET(raw_data!$A$1,MATCH(clean_data!$A4,raw_data!AB:AB,1)-1,MATCH(clean_data!K$1,raw_data!$1:$1,0)-1,,)} -> 11 | L4: {=OFFSET(raw_data!$A$1,MATCH(clean_data!$A4,raw_data!AE:AE,1)-1,MATCH(clean_data!L$1,raw_data!$1:$1,0)-1,,)} -> 113.77 | M4: {=OFFSET(raw_data!$A$1,MATCH(clean_data!$A4,raw_data!AH:AH,1)-1,MATCH(clean_data!M$1,raw_data!$1:$1,0)-1,,)} -> 5.0244 | N4: {=OFFSET(raw_data!$A$1,MATCH(clean_data!$A4,raw_data!AK:AK,1)-1,MATCH(clean_data!N$1,raw_data!$1:$1,0)-1,,)} -> 1327.3096 | O4: {=OFFSET(raw_data!$A$1,MATCH(clean_data!$A4,raw_data!AN:AN,1)-1,MATCH(clean_data!O$1,raw_data!$1:$1,0)-1,,)} -> 120.92 | P4: {=OFFSET(raw_data!$A$1,MATCH(clean_data!$A4,raw_data!AT:AT,1)-1,MATCH(clean_data!P$1,raw_data!$1:$1,0)-1,,)} -> 110.31
A5: =EOMONTH(A4,1) -> 41305 | B5: {=OFFSET(raw_data!$A$1,MATCH(clean_data!$A5,raw_data!A:A,1)-1,MATCH(clean_data!B$1,raw_data!$1:$1,0)-1,,)} -> 97.76 | C5: {=OFFSET(raw_data!$A$1,MATCH(clean_data!$A5,raw_data!D:D,1)-1,MATCH(clean_data!C$1,raw_data!$1:$1,0)-1,,)/INDEX(raw_data!$AR:$AR,MATCH(clean_data!A5,raw_data!$AQ:$AQ,1))} -> 35.56963 | D5: {=OFFSET(raw_data!$A$1,MATCH(clean_data!$A5,raw_data!G:G,1)-1,MATCH(clean_data!D$1,raw_data!$1:$1,0)-1,,)} -> 28.42 | E5: {=OFFSET(raw_data!$A$1,MATCH(clean_data!$A5,raw_data!J:J,1)-1,MATCH(clean_data!E$1,raw_data!$1:$1,0)-1,,)} -> 7.882 | F5: {=OFFSET(raw_data!$A$1,MATCH(clean_data!$A5,raw_data!M:M,1)-1,MATCH(clean_data!F$1,raw_data!$1:$1,0)-1,,)} -> 70.2562 | G5: {=OFFSET(raw_data!$A$1,MATCH(clean_data!$A5,raw_data!P:P,1)-1,MATCH(clean_data!G$1,raw_data!$1:$1,0)-1,,)} -> 134.71 | H5: {=OFFSET(raw_data!$A$1,MATCH(clean_data!$A5,raw_data!S:S,1)-1,MATCH(clean_data!H$1,raw_data!$1:$1,0)-1,,)} -> 51.3264 | I5: {=OFFSET(raw_data!$A$1,MATCH(clean_data!$A5,raw_data!V:V,1)-1,MATCH(clean_data!I$1,raw_data!$1:$1,0)-1,,)} -> 15.94 | J5: {=OFFSET(raw_data!$A$1,MATCH(clean_data!$A5,raw_data!Y:Y,1)-1,MATCH(clean_data!J$1,raw_data!$1:$1,0)-1,,)} -> 42.0651 | K5: {=OFFSET(raw_data!$A$1,MATCH(clean_data!$A5,raw_data!AB:AB,1)-1,MATCH(clean_data!K$1,raw_data!$1:$1,0)-1,,)} -> 10.863 | L5: {=OFFSET(raw_data!$A$1,MATCH(clean_data!$A5,raw_data!AE:AE,1)-1,MATCH(clean_data!L$1,raw_data!$1:$1,0)-1,,)} -> 112.5 | M5: {=OFFSET(raw_data!$A$1,MATCH(clean_data!$A5,raw_data!AH:AH,1)-1,MATCH(clean_data!M$1,raw_data!$1:$1,0)-1,,)} -> 5.19 | N5: {=OFFSET(raw_data!$A$1,MATCH(clean_data!$A5,raw_data!AK:AK,1)-1,MATCH(clean_data!N$1,raw_data!$1:$1,0)-1,,)} -> 1324.7799 | O5: {=OFFSET(raw_data!$A$1,MATCH(clean_data!$A5,raw_data!AN:AN,1)-1,MATCH(clean_data!O$1,raw_data!$1:$1,0)-1,,)} -> 118.31 | P5: {=OFFSET(raw_data!$A$1,MATCH(clean_data!$A5,raw_data!AT:AT,1)-1,MATCH(clean_data!P$1,raw_data!$1:$1,0)-1,,)} -> 109.31
A6: =EOMONTH(A5,1) -> 41333 | B6: {=OFFSET(raw_data!$A$1,MATCH(clean_data!$A6,raw_data!A:A,1)-1,MATCH(clean_data!B$1,raw_data!$1:$1,0)-1,,)} -> 102.97 | C6: {=OFFSET(raw_data!$A$1,MATCH(clean_data!$A6,raw_data!D:D,1)-1,MATCH(clean_data!C$1,raw_data!$1:$1,0)-1,,)/INDEX(raw_data!$AR:$AR,MATCH(clean_data!A6,raw_data!$AQ:$AQ,1))} -> 36.05239 | D6: {=OFFSET(raw_data!$A$1,MATCH(clean_data!$A6,raw_data!G:G,1)-1,MATCH(clean_data!D$1,raw_data!$1:$1,0)-1,,)} -> 30.24 | E6: {=OFFSET(raw_data!$A$1,MATCH(clean_data!$A6,raw_data!J:J,1)-1,MATCH(clean_data!E$1,raw_data!$1:$1,0)-1,,)} -> 8.084 | F6: {=OFFSET(raw_data!$A$1,MATCH(clean_data!$A6,raw_data!M:M,1)-1,MATCH(clean_data!F$1,raw_data!$1:$1,0)-1,,)} -> 70.2562 | G6: {=OFFSET(raw_data!$A$1,MATCH(clean_data!$A6,raw_data!P:P,1)-1,MATCH(clean_data!G$1,raw_data!$1:$1,0)-1,,)} -> 135.63 | H6: {=OFFSET(raw_data!$A$1,MATCH(clean_data!$A6,raw_data!S:S,1)-1,MATCH(clean_data!H$1,raw_data!$1:$1,0)-1,,)} -> 51.8053 | I6: {=OFFSET(raw_data!$A$1,MATCH(clean_data!$A6,raw_data!V:V,1)-1,MATCH(clean_data!I$1,raw_data!$1:$1,0)-1,,)} -> 16 | J6: {=OFFSET(raw_data!$A$1,MATCH(clean_data!$A6,raw_data!Y:Y,1)-1,MATCH(clean_data!J$1,raw_data!$1:$1,0)-1,,)} -> 42.151 | K6: {=OFFSET(raw_data!$A$1,MATCH(clean_data!$A6,raw_data!AB:AB,1)-1,MATCH(clean_data!K$1,raw_data!$1:$1,0)-1,,)} -> 11.002 | L6: {=OFFSET(raw_data!$A$1,MATCH(clean_data!$A6,raw_data!AE:AE,1)-1,MATCH(clean_data!L$1,raw_data!$1:$1,0)-1,,)} -> 112.03 | M6: {=OFFSET(raw_data!$A$1,MATCH(clean_data!$A6,raw_data!AH:AH,1)-1,MATCH(clean_data!M$1,raw_data!$1:$1,0)-1,,)} -> 5.5529 | N6: {=OFFSET(raw_data!$A$1,MATCH(clean_data!$A6,raw_data!AK:AK,1)-1,MATCH(clean_data!N$1,raw_data!$1:$1,0)-1,,)} -> 1330.0289 | O6: {=OFFSET(raw_data!$A$1,MATCH(clean_data!$A6,raw_data!AN:AN,1)-1,MATCH(clean_data!O$1,raw_data!$1:$1,0)-1,,)} -> 116.65 | P6: {=OFFSET(raw_data!$A$1,MATCH(clean_data!$A6,raw_data!AT:AT,1)-1,MATCH(clean_data!P$1,raw_data!$1:$1,0)-1,,)} -> 113.64
A7: =EOMONTH(A6,1) -> 41364 | B7: {=OFFSET(raw_data!$A$1,MATCH(clean_data!$A7,raw_data!A:A,1)-1,MATCH(clean_data!B$1,raw_data!$1:$1,0)-1,,)} -> 108.5 | C7: {=OFFSET(raw_data!$A$1,MATCH(clean_data!$A7,raw_data!D:D,1)-1,MATCH(clean_data!C$1,raw_data!$1:$1,0)-1,,)/INDEX(raw_data!$AR:$AR,MATCH(clean_data!A7,raw_data!$AQ:$AQ,1))} -> 36.575663 | D7: {=OFFSET(raw_data!$A$1,MATCH(clean_data!$A7,raw_data!G:G,1)-1,MATCH(clean_data!D$1,raw_data!$1:$1,0)-1,,)} -> 32.56 | E7: {=OFFSET(raw_data!$A$1,MATCH(clean_data!$A7,raw_data!J:J,1)-1,MATCH(clean_data!E$1,raw_data!$1:$1,0)-1,,)} -> 8.059 | F7: {=OFFSET(raw_data!$A$1,MATCH(clean_data!$A7,raw_data!M:M,1)-1,MATCH(clean_data!F$1,raw_data!$1:$1,0)-1,,)} -> 70.2562 | G7: {=OFFSET(raw_data!$A$1,MATCH(clean_data!$A7,raw_data!P:P,1)-1,MATCH(clean_data!G$1,raw_data!$1:$1,0)-1,,)} -> 136.51 | H7: {=OFFSET(raw_data!$A$1,MATCH(clean_data!$A7,raw_data!S:S,1)-1,MATCH(clean_data!H$1,raw_data!$1:$1,0)-1,,)} -> 52.2573 | I7: {=OFFSET(raw_data!$A$1,MATCH(clean_data!$A7,raw_data!V:V,1)-1,MATCH(clean_data!I$1,raw_data!$1:$1,0)-1,,)} -> 16.06 | J7: {=OFFSET(raw_data!$A$1,MATCH(clean_data!$A7,raw_data!Y:Y,1)-1,MATCH(clean_data!J$1,raw_data!$1:$1,0)-1,,)} -> 42.1376 | K7: {=OFFSET(raw_data!$A$1,MATCH(clean_data!$A7,raw_data!AB:AB,1)-1,MATCH(clean_data!K$1,raw_data!$1:$1,0)-1,,)} -> 11.053 | L7: {=OFFSET(raw_data!$A$1,MATCH(clean_data!$A7,raw_data!AE:AE,1)-1,MATCH(clean_data!L$1,raw_data!$1:$1,0)-1,,)} -> 111.72 | M7: {=OFFSET(raw_data!$A$1,MATCH(clean_data!$A7,raw_data!AH:AH,1)-1,MATCH(clean_data!M$1,raw_data!$1:$1,0)-1,,)} -> 5.5529 | N7: {=OFFSET(raw_data!$A$1,MATCH(clean_data!$A7,raw_data!AK:AK,1)-1,MATCH(clean_data!N$1,raw_data!$1:$1,0)-1,,)} -> 1336.8807 | O7: {=OFFSET(raw_data!$A$1,MATCH(clean_data!$A7,raw_data!AN:AN,1)-1,MATCH(clean_data!O$1,raw_data!$1:$1,0)-1,,)} -> 120.09 | P7: {=OFFSET(raw_data!$A$1,MATCH(clean_data!$A7,raw_data!AT:AT,1)-1,MATCH(clean_data!P$1,raw_data!$1:$1,0)-1,,)} -> 117.86
A8: =EOMONTH(A7,1) -> 41394 | B8: {=OFFSET(raw_data!$A$1,MATCH(clean_data!$A8,raw_data!A:A,1)-1,MATCH(clean_data!B$1,raw_data!$1:$1,0)-1,,)} -> 107.4 | C8: {=OFFSET(raw_data!$A$1,MATCH(clean_data!$A8,raw_data!D:D,1)-1,MATCH(clean_data!C$1,raw_data!$1:$1,0)-1,,)/INDEX(raw_data!$AR:$AR,MATCH(clean_data!A8,raw_data!$AQ:$AQ,1))} -> 37.096529 | D8: {=OFFSET(raw_data!$A$1,MATCH(clean_data!$A8,raw_data!G:G,1)-1,MATCH(clean_data!D$1,raw_data!$1:$1,0)-1,,)} -> 34.43 | E8: {=OFFSET(raw_data!$A$1,MATCH(clean_data!$A8,raw_data!J:J,1)-1,MATCH(clean_data!E$1,raw_data!$1:$1,0)-1,,)} -> 7.937 | F8: {=OFFSET(raw_data!$A$1,MATCH(clean_data!$A8,raw_data!M:M,1)-1,MATCH(clean_data!F$1,raw_data!$1:$1,0)-1,,)} -> 70.2562 | G8: {=OFFSET(raw_data!$A$1,MATCH(clean_data!$A8,raw_data!P:P,1)-1,MATCH(clean_data!G$1,raw_data!$1:$1,0)-1,,)} -> 140.61 | H8: {=OFFSET(raw_data!$A$1,MATCH(clean_data!$A8,raw_data!S:S,1)-1,MATCH(clean_data!H$1,raw_data!$1:$1,0)-1,,)} -> 53.3653 | I8: {=OFFSET(raw_data!$A$1,MATCH(clean_data!$A8,raw_data!V:V,1)-1,MATCH(clean_data!I$1,raw_data!$1:$1,0)-1,,)} -> 16.44 | J8: {=OFFSET(raw_data!$A$1,MATCH(clean_data!$A8,raw_data!Y:Y,1)-1,MATCH(clean_data!J$1,raw_data!$1:$1,0)-1,,)} -> 42.2017 | K8: {=OFFSET(raw_data!$A$1,MATCH(clean_data!$A8,raw_data!AB:AB,1)-1,MATCH(clean_data!K$1,raw_data!$1:$1,0)-1,,)} -> 11.211 | L8: {=OFFSET(raw_data!$A$1,MATCH(clean_data!$A8,raw_data!AE:AE,1)-1,MATCH(clean_data!L$1,raw_data!$1:$1,0)-1,,)} -> 114.35 | M8: {=OFFSET(raw_data!$A$1,MATCH(clean_data!$A8,raw_data!AH:AH,1)-1,MATCH(clean_data!M$1,raw_data!$1:$1,0)-1,,)} -> 5.4778 | N8: {=OFFSET(raw_data!$A$1,MATCH(clean_data!$A8,raw_data!AK:AK,1)-1,MATCH(clean_data!N$1,raw_data!$1:$1,0)-1,,)} -> 1351.7261 | O8: {=OFFSET(raw_data!$A$1,MATCH(clean_data!$A8,raw_data!AN:AN,1)-1,MATCH(clean_data!O$1,raw_data!$1:$1,0)-1,,)} -> 107.43 | P8: {=OFFSET(raw_data!$A$1,MATCH(clean_data!$A8,raw_data!AT:AT,1)-1,MATCH(clean_data!P$1,raw_data!$1:$1,0)-1,,)} -> 116.51
A9: =EOMONTH(A8,1) -> 41425 | B9: {=OFFSET(raw_data!$A$1,MATCH(clean_data!$A9,raw_data!A:A,1)-1,MATCH(clean_data!B$1,raw_data!$1:$1,0)-1,,)} -> 113.97 | C9: {=OFFSET(raw_data!$A$1,MATCH(clean_data!$A9,raw_data!D:D,1)-1,MATCH(clean_data!C$1,raw_data!$1:$1,0)-1,,)/INDEX(raw_data!$AR:$AR,MATCH(clean_data!A9,raw_data!$AQ:$AQ,1))} -> 38.972229 | D9: {=OFFSET(raw_data!$A$1,MATCH(clean_data!$A9,raw_data!G:G,1)-1,MATCH(clean_data!D$1,raw_data!$1:$1,0)-1,,)} -> 32.75 | E9: {=OFFSET(raw_data!$A$1,MATCH(clean_data!$A9,raw_data!J:J,1)-1,MATCH(clean_data!E$1,raw_data!$1:$1,0)-1,,)} -> 7.82 | F9: {=OFFSET(raw_data!$A$1,MATCH(clean_data!$A9,raw_data!M:M,1)-1,MATCH(clean_data!F$1,raw_data!$1:$1,0)-1,,)} -> 70.2562 | G9: {=OFFSET(raw_data!$A$1,MATCH(clean_data!$A9,raw_data!P:P,1)-1,MATCH(clean_data!G$1,raw_data!$1:$1,0)-1,,)} -> 138.39 | H9: {=OFFSET(raw_data!$A$1,MATCH(clean_data!$A9,raw_data!S:S,1)-1,MATCH(clean_data!H$1,raw_data!$1:$1,0)-1,,)} -> 51.9879 | I9: {=OFFSET(raw_data!$A$1,MATCH(clean_data!$A9,raw_data!V:V,1)-1,MATCH(clean_data!I$1,raw_data!$1:$1,0)-1,,)} -> 16.45 | J9: {=OFFSET(raw_data!$A$1,MATCH(clean_data!$A9,raw_data!Y:Y,1)-1,MATCH(clean_data!J$1,raw_data!$1:$1,0)-1,,)} -> 42.2055 | K9: {=OFFSET(raw_data!$A$1,MATCH(clean_data!$A9,raw_data!AB:AB,1)-1,MATCH(clean_data!K$1,raw_data!$1:$1,0)-1,,)} -> 11.185 | L9: {=OFFSET(raw_data!$A$1,MATCH(clean_data!$A9,raw_data!AE:AE,1)-1,MATCH(clean_data!L$1,raw_data!$1:$1,0)-1,,)} -> 110.41 | M9: {=OFFSET(raw_data!$A$1,MATCH(clean_data!$A9,raw_data!AH:AH,1)-1,MATCH(clean_data!M$1,raw_data!$1:$1,0)-1,,)} -> 5.6085 | N9: {=OFFSET(raw_data!$A$1,MATCH(clean_data!$A9,raw_data!AK:AK,1)-1,MATCH(clean_data!N$1,raw_data!$1:$1,0)-1,,)} -> 1356.0614 | O9: {=OFFSET(raw_data!$A$1,MATCH(clean_data!$A9,raw_data!AN:AN,1)-1,MATCH(clean_data!O$1,raw_data!$1:$1,0)-1,,)} -> 103.53 | P9: {=OFFSET(raw_data!$A$1,MATCH(clean_data!$A9,raw_data!AT:AT,1)-1,MATCH(clean_data!P$1,raw_data!$1:$1,0)-1,,)} -> 118.23
A10: =EOMONTH(A9,1) -> 41455 | B10: {=OFFSET(raw_data!$A$1,MATCH(clean_data!$A10,raw_data!A:A,1)-1,MATCH(clean_data!B$1,raw_data!$1:$1,0)-1,,)} -> 110.6 | C10: {=OFFSET(raw_data!$A$1,MATCH(clean_data!$A10,raw_data!D:D,1)-1,MATCH(clean_data!C$1,raw_data!$1:$1,0)-1,,)/INDEX(raw_data!$AR:$AR,MATCH(clean_data!A10,raw_data!$AQ:$AQ,1))} -> 36.667948 | D10: {=OFFSET(raw_data!$A$1,MATCH(clean_data!$A10,raw_data!G:G,1)-1,MATCH(clean_data!D$1,raw_data!$1:$1,0)-1,,)} -> 33.77 | E10: {=OFFSET(raw_data!$A$1,MATCH(clean_data!$A10,raw_data!J:J,1)-1,MATCH(clean_data!E$1,raw_data!$1:$1,0)-1,,)} -> 7.25 | F10: {=OFFSET(raw_data!$A$1,MATCH(clean_data!$A10,raw_data!M:M,1)-1,MATCH(clean_data!F$1,raw_data!$1:$1,0)-1,,)} -> 70.2562 | G10: {=OFFSET(raw_data!$A$1,MATCH(clean_data!$A10,raw_data!P:P,1)-1,MATCH(clean_data!G$1,raw_data!$1:$1,0)-1,,)} -> 135.71 | H10: {=OFFSET(raw_data!$A$1,MATCH(clean_data!$A10,raw_data!S:S,1)-1,MATCH(clean_data!H$1,raw_data!$1:$1,0)-1,,)} -> 51.11 | I10: {=OFFSET(raw_data!$A$1,MATCH(clean_data!$A10,raw_data!V:V,1)-1,MATCH(clean_data!I$1,raw_data!$1:$1,0)-1,,)} -> 16.02 | J10: {=OFFSET(raw_data!$A$1,MATCH(clean_data!$A10,raw_data!Y:Y,1)-1,MATCH(clean_data!J$1,raw_data!$1:$1,0)-1,,)} -> 42.063 | K10: {=OFFSET(raw_data!$A$1,MATCH(clean_data!$A10,raw_data!AB:AB,1)-1,MATCH(clean_data!K$1,raw_data!$1:$1,0)-1,,)} -> 10.995 | L10: {=OFFSET(raw_data!$A$1,MATCH(clean_data!$A10,raw_data!AE:AE,1)-1,MATCH(clean_data!L$1,raw_data!$1:$1,0)-1,,)} -> 105 | M10: {=OFFSET(raw_data!$A$1,MATCH(clean_data!$A10,raw_data!AH:AH,1)-1,MATCH(clean_data!M$1,raw_data!$1:$1,0)-1,,)} -> 5.6085 | N10: {=OFFSET(raw_data!$A$1,MATCH(clean_data!$A10,raw_data!AK:AK,1)-1,MATCH(clean_data!N$1,raw_data!$1:$1,0)-1,,)} -> 1345.2466 | O10: {=OFFSET(raw_data!$A$1,MATCH(clean_data!$A10,raw_data!AN:AN,1)-1,MATCH(clean_data!O$1,raw_data!$1:$1,0)-1,,)} -> 90.07 | P10: {=OFFSET(raw_data!$A$1,MATCH(clean_data!$A10,raw_data!AT:AT,1)-1,MATCH(clean_data!P$1,raw_data!$1:$1,0)-1,,)} -> 115.35
A11: =EOMONTH(A10,1) -> 41486 | B11: {=OFFSET(raw_data!$A$1,MATCH(clean_data!$A11,raw_data!A:A,1)-1,MATCH(clean_data!B$1,raw_data!$1:$1,0)-1,,)} -> 113.93 | C11: {=OFFSET(raw_data!$A$1,MATCH(clean_data!$A11,raw_data!D:D,1)-1,MATCH(clean_data!C$1,raw_data!$1:$1,0)-1,,)/INDEX(raw_data!$AR:$AR,MATCH(clean_data!A11,raw_data!$AQ:$AQ,1))} -> 38.174711 | D11: {=OFFSET(raw_data!$A$1,MATCH(clean_data!$A11,raw_data!G:G,1)-1,MATCH(clean_data!D$1,raw_data!$1:$1,0)-1,,)} -> 32.98 | E11: {=OFFSET(raw_data!$A$1,MATCH(clean_data!$A11,raw_data!J:J,1)-1,MATCH(clean_data!E$1,raw_data!$1:$1,0)-1,,)} -> 7.217 | F11: {=OFFSET(raw_data!$A$1,MATCH(clean_data!$A11,raw_data!M:M,1)-1,MATCH(clean_data!F$1,raw_data!$1:$1,0)-1,,)} -> 70.2562 | G11: {=OFFSET(raw_data!$A$1,MATCH(clean_data!$A11,raw_data!P:P,1)-1,MATCH(clean_data!G$1,raw_data!$1:$1,0)-1,,)} -> 137.13 | H11: {=OFFSET(raw_data!$A$1,MATCH(clean_data!$A11,raw_data!S:S,1)-1,MATCH(clean_data!H$1,raw_data!$1:$1,0)-1,,)} -> 52.5685 | I11: {=OFFSET(raw_data!$A$1,MATCH(clean_data!$A11,raw_data!V:V,1)-1,MATCH(clean_data!I$1,raw_data!$1:$1,0)-1,,)} -> 16.34 | J11: {=OFFSET(raw_data!$A$1,MATCH(clean_data!$A11,raw_data!Y:Y,1)-1,MATCH(clean_data!J$1,raw_data!$1:$1,0)-1,,)} -> 42.1891 | K11: {=OFFSET(raw_data!$A$1,MATCH(clean_data!$A11,raw_data!AB:AB,1)-1,MATCH(clean_data!K$1,raw_data!$1:$1,0)-1,,)} -> 11.091 | L11: {=OFFSET(raw_data!$A$1,MATCH(clean_data!$A11,raw_data!AE:AE,1)-1,MATCH(clean_data!L$1,raw_data!$1:$1,0)-1,,)} -> 105.99 | M11: {=OFFSET(raw_data!$A$1,MATCH(clean_data!$A11,raw_data!AH:AH,1)-1,MATCH(clean_data!M$1,raw_data!$1:$1,0)-1,,)} -> 5.865 | N11: {=OFFSET(raw_data!$A$1,MATCH(clean_data!$A11,raw_data!AK:AK,1)-1,MATCH(clean_data!N$1,raw_data!$1:$1,0)-1,,)} -> 1357.8336 | O11: {=OFFSET(raw_data!$A$1,MATCH(clean_data!$A11,raw_data!AN:AN,1)-1,MATCH(clean_data!O$1,raw_data!$1:$1,0)-1,,)} -> 95.06 | P11: {=OFFSET(raw_data!$A$1,MATCH(clean_data!$A11,raw_data!AT:AT,1)-1,MATCH(clean_data!P$1,raw_data!$1:$1,0)-1,,)} -> 116.33
A12: =EOMONTH(A11,1) -> 41517 | B12: {=OFFSET(raw_data!$A$1,MATCH(clean_data!$A12,raw_data!A:A,1)-1,MATCH(clean_data!B$1,raw_data!$1:$1,0)-1,,)} -> 110.64 | C12: {=OFFSET(raw_data!$A$1,MATCH(clean_data!$A12,raw_data!D:D,1)-1,MATCH(clean_data!C$1,raw_data!$1:$1,0)-1,,)/INDEX(raw_data!$AR:$AR,MATCH(clean_data!A12,raw_data!$AQ:$AQ,1))} -> 37.789291 | D12: {=OFFSET(raw_data!$A$1,MATCH(clean_data!$A12,raw_data!G:G,1)-1,MATCH(clean_data!D$1,raw_data!$1:$1,0)-1,,)} -> 32.22 | E12: {=OFFSET(raw_data!$A$1,MATCH(clean_data!$A12,raw_data!J:J,1)-1,MATCH(clean_data!E$1,raw_data!$1:$1,0)-1,,)} -> 7.068 | F12: {=OFFSET(raw_data!$A$1,MATCH(clean_data!$A12,raw_data!M:M,1)-1,MATCH(clean_data!F$1,raw_data!$1:$1,0)-1,,)} -> 66.1635 | G12: {=OFFSET(raw_data!$A$1,MATCH(clean_data!$A12,raw_data!P:P,1)-1,MATCH(clean_data!G$1,raw_data!$1:$1,0)-1,,)} -> 136.26 | H12: {=OFFSET(raw_data!$A$1,MATCH(clean_data!$A12,raw_data!S:S,1)-1,MATCH(clean_data!H$1,raw_data!$1:$1,0)-1,,)} -> 51.8999 | I12: {=OFFSET(raw_data!$A$1,MATCH(clean_data!$A12,raw_data!V:V,1)-1,MATCH(clean_data!I$1,raw_data!$1:$1,0)-1,,)} -> 16.37 | J12: {=OFFSET(raw_data!$A$1,MATCH(clean_data!$A12,raw_data!Y:Y,1)-1,MATCH(clean_data!J$1,raw_data!$1:$1,0)-1,,)} -> 42.1528 | K12: {=OFFSET(raw_data!$A$1,MATCH(clean_data!$A12,raw_data!AB:AB,1)-1,MATCH(clean_data!K$1,raw_data!$1:$1,0)-1,,)} -> 11.066 | L12: {=OFFSET(raw_data!$A$1,MATCH(clean_data!$A12,raw_data!AE:AE,1)-1,MATCH(clean_data!L$1,raw_data!$1:$1,0)-1,,)} -> 103.07 | M12: {=OFFSET(raw_data!$A$1,MATCH(clean_data!$A12,raw_data!AH:AH,1)-1,MATCH(clean_data!M$1,raw_data!$1:$1,0)-1,,)} -> 5.572 | N12: {=OFFSET(raw_data!$A$1,MATCH(clean_data!$A12,raw_data!AK:AK,1)-1,MATCH(clean_data!N$1,raw_data!$1:$1,0)-1,,)} -> 1354.4659 | O12: {=OFFSET(raw_data!$A$1,MATCH(clean_data!$A12,raw_data!AN:AN,1)-1,MATCH(clean_data!O$1,raw_data!$1:$1,0)-1,,)} -> 102.27 | P12: {=OFFSET(raw_data!$A$1,MATCH(clean_data!$A12,raw_data!AT:AT,1)-1,MATCH(clean_data!P$1,raw_data!$1:$1,0)-1,,)} -> 115.89
A13: =EOMONTH(A12,1) -> 41547 | B13: {=OFFSET(raw_data!$A$1,MATCH(clean_data!$A13,raw_data!A:A,1)-1,MATCH(clean_data!B$1,raw_data!$1:$1,0)-1,,)} -> 111.16 | C13: {=OFFSET(raw_data!$A$1,MATCH(clean_data!$A13,raw_data!D:D,1)-1,MATCH(clean_data!C$1,raw_data!$1:$1,0)-1,,)/INDEX(raw_data!$AR:$AR,MATCH(clean_data!A13,raw_data!$AQ:$AQ,1))} -> 39.327961 | D13: {=OFFSET(raw_data!$A$1,MATCH(clean_data!$A13,raw_data!G:G,1)-1,MATCH(clean_data!D$1,raw_data!$1:$1,0)-1,,)} -> 34.21 | E13: {=OFFSET(raw_data!$A$1,MATCH(clean_data!$A13,raw_data!J:J,1)-1,MATCH(clean_data!E$1,raw_data!$1:$1,0)-1,,)} -> 7.424 | F13: {=OFFSET(raw_data!$A$1,MATCH(clean_data!$A13,raw_data!M:M,1)-1,MATCH(clean_data!F$1,raw_data!$1:$1,0)-1,,)} -> 65.1275 | G13: {=OFFSET(raw_data!$A$1,MATCH(clean_data!$A13,raw_data!P:P,1)-1,MATCH(clean_data!G$1,raw_data!$1:$1,0)-1,,)} -> 137.6 | H13: {=OFFSET(raw_data!$A$1,MATCH(clean_data!$A13,raw_data!S:S,1)-1,MATCH(clean_data!H$1,raw_data!$1:$1,0)-1,,)} -> 52.3083 | I13: {=OFFSET(raw_data!$A$1,MATCH(clean_data!$A13,raw_data!V:V,1)-1,MATCH(clean_data!I$1,raw_data!$1:$1,0)-1,,)} -> 16.57 | J13: {=OFFSET(raw_data!$A$1,MATCH(clean_data!$A13,raw_data!Y:Y,1)-1,MATCH(clean_data!J$1,raw_data!$1:$1,0)-1,,)} -> 42.2841 | K13: {=OFFSET(raw_data!$A$1,MATCH(clean_data!$A13,raw_data!AB:AB,1)-1,MATCH(clean_data!K$1,raw_data!$1:$1,0)-1,,)} -> 11.142 | L13: {=OFFSET(raw_data!$A$1,MATCH(clean_data!$A13,raw_data!AE:AE,1)-1,MATCH(clean_data!L$1,raw_data!$1:$1,0)-1,,)} -> 105.74 | M13: {=OFFSET(raw_data!$A$1,MATCH(clean_data!$A13,raw_data!AH:AH,1)-1,MATCH(clean_data!M$1,raw_data!$1:$1,0)-1,,)} -> 5.7306 | N13: {=OFFSET(raw_data!$A$1,MATCH(clean_data!$A13,raw_data!AK:AK,1)-1,MATCH(clean_data!N$1,raw_data!$1:$1,0)-1,,)} -> 1365.3722 | O13: {=OFFSET(raw_data!$A$1,MATCH(clean_data!$A13,raw_data!AN:AN,1)-1,MATCH(clean_data!O$1,raw_data!$1:$1,0)-1,,)} -> 94.63 | P13: {=OFFSET(raw_data!$A$1,MATCH(clean_data!$A13,raw_data!AT:AT,1)-1,MATCH(clean_data!P$1,raw_data!$1:$1,0)-1,,)} -> 115.8
A14: =EOMONTH(A13,1) -> 41578 | B14: {=OFFSET(raw_data!$A$1,MATCH(clean_data!$A14,raw_data!A:A,1)-1,MATCH(clean_data!B$1,raw_data!$1:$1,0)-1,,)} -> 116.27 | C14: {=OFFSET(raw_data!$A$1,MATCH(clean_data!$A14,raw_data!D:D,1)-1,MATCH(clean_data!C$1,raw_data!$1:$1,0)-1,,)/INDEX(raw_data!$AR:$AR,MATCH(clean_data!A14,raw_data!$AQ:$AQ,1))} -> 41.515754 | D14: {=OFFSET(raw_data!$A$1,MATCH(clean_data!$A14,raw_data!G:G,1)-1,MATCH(clean_data!D$1,raw_data!$1:$1,0)-1,,)} -> 34.27 | E14: {=OFFSET(raw_data!$A$1,MATCH(clean_data!$A14,raw_data!J:J,1)-1,MATCH(clean_data!E$1,raw_data!$1:$1,0)-1,,)} -> 7.715 | F14: {=OFFSET(raw_data!$A$1,MATCH(clean_data!$A14,raw_data!M:M,1)-1,MATCH(clean_data!F$1,raw_data!$1:$1,0)-1,,)} -> 64.0916 | G14: {=OFFSET(raw_data!$A$1,MATCH(clean_data!$A14,raw_data!P:P,1)-1,MATCH(clean_data!G$1,raw_data!$1:$1,0)-1,,)} -> 140.04 | H14: {=OFFSET(raw_data!$A$1,MATCH(clean_data!$A14,raw_data!S:S,1)-1,MATCH(clean_data!H$1,raw_data!$1:$1,0)-1,,)} -> 53.6254 | I14: {=OFFSET(raw_data!$A$1,MATCH(clean_data!$A14,raw_data!V:V,1)-1,MATCH(clean_data!I$1,raw_data!$1:$1,0)-1,,)} -> 16.91 | J14: {=OFFSET(raw_data!$A$1,MATCH(clean_data!$A14,raw_data!Y:Y,1)-1,MATCH(clean_data!J$1,raw_data!$1:$1,0)-1,,)} -> 42.3851 | K14: {=OFFSET(raw_data!$A$1,MATCH(clean_data!$A14,raw_data!AB:AB,1)-1,MATCH(clean_data!K$1,raw_data!$1:$1,0)-1,,)} -> 11.272 | L14: {=OFFSET(raw_data!$A$1,MATCH(clean_data!$A14,raw_data!AE:AE,1)-1,MATCH(clean_data!L$1,raw_data!$1:$1,0)-1,,)} -> 108.04 | M14: {=OFFSET(raw_data!$A$1,MATCH(clean_data!$A14,raw_data!AH:AH,1)-1,MATCH(clean_data!M$1,raw_data!$1:$1,0)-1,,)} -> 6.0496 | N14: {=OFFSET(raw_data!$A$1,MATCH(clean_data!$A14,raw_data!AK:AK,1)-1,MATCH(clean_data!N$1,raw_data!$1:$1,0)-1,,)} -> 1374.6619 | O14: {=OFFSET(raw_data!$A$1,MATCH(clean_data!$A14,raw_data!AN:AN,1)-1,MATCH(clean_data!O$1,raw_data!$1:$1,0)-1,,)} -> 93.7 | P14: {=OFFSET(raw_data!$A$1,MATCH(clean_data!$A14,raw_data!AT:AT,1)-1,MATCH(clean_data!P$1,raw_data!$1:$1,0)-1,,)} -> 117.98
... A139: =EOMONTH(A138,1) -> 45382 | B139: {=OFFSET(raw_data!$A$1,MATCH(clean_data!$A139,raw_data!A:A,1)-1,MATCH(clean_data!B$1,raw_data!$1:$1,0)-1,,)} -> 511.27 | C139: {=OFFSET(raw_data!$A$1,MATCH(clean_data!$A139,raw_data!D:D,1)-1,MATCH(clean_data!C$1,raw_data!$1:$1,0)-1,,)/INDEX(raw_data!$AR:$AR,MATCH(clean_data!A139,raw_data!$AQ:$AQ,1))} -> 117.27205 | D139: {=OFFSET(raw_data!$A$1,MATCH(clean_data!$A139,raw_data!G:G,1)-1,MATCH(clean_data!D$1,raw_data!$1:$1,0)-1,,)} -> 76.416 | E139: {=OFFSET(raw_data!$A$1,MATCH(clean_data!$A139,raw_data!J:J,1)-1,MATCH(clean_data!E$1,raw_data!$1:$1,0)-1,,)} -> 11.753 | F139: {=OFFSET(raw_data!$A$1,MATCH(clean_data!$A139,raw_data!M:M,1)-1,MATCH(clean_data!F$1,raw_data!$1:$1,0)-1,,)} -> 89.17 | G139: {=OFFSET(raw_data!$A$1,MATCH(clean_data!$A139,raw_data!P:P,1)-1,MATCH(clean_data!G$1,raw_data!$1:$1,0)-1,,)} -> 163.19 | H139: {=OFFSET(raw_data!$A$1,MATCH(clean_data!$A139,raw_data!S:S,1)-1,MATCH(clean_data!H$1,raw_data!$1:$1,0)-1,,)} -> 76.926 | I139: {=OFFSET(raw_data!$A$1,MATCH(clean_data!$A139,raw_data!V:V,1)-1,MATCH(clean_data!I$1,raw_data!$1:$1,0)-1,,)} -> 22.46 | J139: {=OFFSET(raw_data!$A$1,MATCH(clean_data!$A139,raw_data!Y:Y,1)-1,MATCH(clean_data!J$1,raw_data!$1:$1,0)-1,,)} -> 50.9478 | K139: {=OFFSET(raw_data!$A$1,MATCH(clean_data!$A139,raw_data!AB:AB,1)-1,MATCH(clean_data!K$1,raw_data!$1:$1,0)-1,,)} -> 13.076 | L139: {=OFFSET(raw_data!$A$1,MATCH(clean_data!$A139,raw_data!AE:AE,1)-1,MATCH(clean_data!L$1,raw_data!$1:$1,0)-1,,)} -> 138.76 | M139: {=OFFSET(raw_data!$A$1,MATCH(clean_data!$A139,raw_data!AH:AH,1)-1,MATCH(clean_data!M$1,raw_data!$1:$1,0)-1,,)} -> 20.5 | N139: {=OFFSET(raw_data!$A$1,MATCH(clean_data!$A139,raw_data!AK:AK,1)-1,MATCH(clean_data!N$1,raw_data!$1:$1,0)-1,,)} -> 1573.7451 | O139: {=OFFSET(raw_data!$A$1,MATCH(clean_data!$A139,raw_data!AN:AN,1)-1,MATCH(clean_data!O$1,raw_data!$1:$1,0)-1,,)} -> 189.36 | P139: {=OFFSET(raw_data!$A$1,MATCH(clean_data!$A139,raw_data!AT:AT,1)-1,MATCH(clean_data!P$1,raw_data!$1:$1,0)-1,,)} -> 239.37

Sheet rebased
A1: =clean_data!A1 -> Dates | B1: =clean_data!B1 -> CSSPX.MI | C1: =clean_data!C1 -> C50.PA | D1: =clean_data!D1 -> DBXJ.XETRA | E1: =clean_data!E1 -> LEM.PA | F1: =clean_data!F1 -> TSYE.PA | G1: =clean_data!G1 -> MTD.PA | H1: =clean_data!H1 -> HYG.US | ... M1: =clean_data!M1 -> NBPVF.US | N1: =clean_data!O1 -> GBS.MI | O1: =clean_data!P1 -> LU0565135745.EUFUND
A2: =clean_data!A2 -> 41213 | B2: =clean_data!B2/clean_data!B$2 -> 1 | C2: =clean_data!C2/clean_data!C$2 -> 1 | D2: =clean_data!D2/clean_data!D$2 -> 1 | E2: =clean_data!E2/clean_data!E$2 -> 1 | F2: =clean_data!F2/clean_data!F$2 -> 1 | G2: =clean_data!G2/clean_data!G$2 -> 1 | H2: =clean_data!H2/clean_data!H$2 -> 1 | I2: =clean_data!I2/clean_data!I$2 -> 1 | ... M2: =clean_data!M2/clean_data!M$2 -> 1 | N2: =clean_data!O2/clean_data!O$2 -> 1 | O2: =clean_data!P2/clean_data!P$2 -> 1
A3: =clean_data!A3 -> 41243 | B3: =clean_data!B3/clean_data!B$2 -> 1.0025078 | C3: =clean_data!C3/clean_data!C$2 -> 1.0285934 | D3: =clean_data!D3/clean_data!D$2 -> 1.0216418 | E3: =clean_data!E3/clean_data!E$2 -> 1.0100522 | F3: =clean_data!F3/clean_data!F$2 -> 1.012692 | G3: =clean_data!G3/clean_data!G$2 -> 1.0188223 | H3: =clean_data!H3/clean_data!H$2 -> 1.010515 | I3: =clean_data!I3/clean_data!I$2 -> 1.0178453 | ... M3: =clean_data!M3/clean_data!M$2 -> 1 | N3: =clean_data!O3/clean_data!O$2 -> 0.99097698 | O3: =clean_data!P3/clean_data!P$2 -> 0.9996355
A4: =clean_data!A4 -> 41274 | B4: =clean_data!B4/clean_data!B$2 -> 0.98652038 | C4: =clean_data!C4/clean_data!C$2 -> 1.0300911 | D4: =clean_data!D4/clean_data!D$2 -> 1.0608209 | E4: =clean_data!E4/clean_data!E$2 -> 1.0472585 | F4: =clean_data!F4/clean_data!F$2 -> 0.99066111 | G4: =clean_data!G4/clean_data!G$2 -> 1.0244161 | H4: =clean_data!H4/clean_data!H$2 -> 1.0246758 | I4: =clean_data!I4/clean_data!I$2 -> 1.0442829 | ... M4: =clean_data!M4/clean_data!M$2 -> 1.0340825 | N4: =clean_data!O4/clean_data!O$2 -> 0.9405725 | O4: =clean_data!P4/clean_data!P$2 -> 1.0051941
A5: =clean_data!A5 -> 41305 | B5: =clean_data!B5/clean_data!B$2 -> 1.0215256 | C5: =clean_data!C5/clean_data!C$2 -> 1.0353339 | D5: =clean_data!D5/clean_data!D$2 -> 1.0604478 | E5: =clean_data!E5/clean_data!E$2 -> 1.0289817 | F5: =clean_data!F5/clean_data!F$2 -> 0.99066111 | G5: =clean_data!G5/clean_data!G$2 -> 1.0182931 | H5: =clean_data!H5/clean_data!H$2 -> 1.0281875 | I5: =clean_data!I5/clean_data!I$2 -> 1.053536 | ... M5: =clean_data!M5/clean_data!M$2 -> 1.068165 | N5: =clean_data!O5/clean_data!O$2 -> 0.92027069 | O5: =clean_data!P5/clean_data!P$2 -> 0.99608165
A6: =clean_data!A6 -> 41333 | B6: =clean_data!B6/clean_data!B$2 -> 1.0759666 | C6: =clean_data!C6/clean_data!C$2 -> 1.0493857 | D6: =clean_data!D6/clean_data!D$2 -> 1.1283582 | E6: =clean_data!E6/clean_data!E$2 -> 1.0553525 | F6: =clean_data!F6/clean_data!F$2 -> 0.99066111 | G6: =clean_data!G6/clean_data!G$2 -> 1.0252476 | H6: =clean_data!H6/clean_data!H$2 -> 1.037781 | I6: =clean_data!I6/clean_data!I$2 -> 1.0575017 | ... M6: =clean_data!M6/clean_data!M$2 -> 1.1428542 | N6: =clean_data!O6/clean_data!O$2 -> 0.90735843 | O6: =clean_data!P6/clean_data!P$2 -> 1.0355385
A7: =clean_data!A7 -> 41364 | B7: =clean_data!B7/clean_data!B$2 -> 1.1337513 | C7: =clean_data!C7/clean_data!C$2 -> 1.0646167 | D7: =clean_data!D7/clean_data!D$2 -> 1.2149254 | E7: =clean_data!E7/clean_data!E$2 -> 1.0520888 | F7: =clean_data!F7/clean_data!F$2 -> 0.99066111 | G7: =clean_data!G7/clean_data!G$2 -> 1.0318996 | H7: =clean_data!H7/clean_data!H$2 -> 1.0468356 | I7: =clean_data!I7/clean_data!I$2 -> 1.0614673 | ... M7: =clean_data!M7/clean_data!M$2 -> 1.1428542 | N7: =clean_data!O7/clean_data!O$2 -> 0.93411637 | O7: =clean_data!P7/clean_data!P$2 -> 1.0739931
A8: =clean_data!A8 -> 41394 | B8: =clean_data!B8/clean_data!B$2 -> 1.1222571 | C8: =clean_data!C8/clean_data!C$2 -> 1.0797777 | D8: =clean_data!D8/clean_data!D$2 -> 1.2847015 | E8: =clean_data!E8/clean_data!E$2 -> 1.0361619 | F8: =clean_data!F8/clean_data!F$2 -> 0.99066111 | G8: =clean_data!G8/clean_data!G$2 -> 1.0628921 | H8: =clean_data!H8/clean_data!H$2 -> 1.0690314 | I8: =clean_data!I8/clean_data!I$2 -> 1.0865829 | ... M8: =clean_data!M8/clean_data!M$2 -> 1.1273977 | N8: =clean_data!O8/clean_data!O$2 -> 0.83564095 | O8: =clean_data!P8/clean_data!P$2 -> 1.0616913
A9: =clean_data!A9 -> 41425 | B9: =clean_data!B9/clean_data!B$2 -> 1.1909091 | C9: =clean_data!C9/clean_data!C$2 -> 1.1343741 | D9: =clean_data!D9/clean_data!D$2 -> 1.2220149 | E9: =clean_data!E9/clean_data!E$2 -> 1.0208877 | F9: =clean_data!F9/clean_data!F$2 -> 0.99066111 | G9: =clean_data!G9/clean_data!G$2 -> 1.0461108 | H9: =clean_data!H9/clean_data!H$2 -> 1.0414389 | I9: =clean_data!I9/clean_data!I$2 -> 1.0872439 | ... M9: =clean_data!M9/clean_data!M$2 -> 1.1542974 | N9: =clean_data!O9/clean_data!O$2 -> 0.80530492 | O9: =clean_data!P9/clean_data!P$2 -> 1.0773647
A10: =clean_data!A10 -> 41455 | B10: =clean_data!B10/clean_data!B$2 -> 1.1556949 | C10: =clean_data!C10/clean_data!C$2 -> 1.0673029 | D10: =clean_data!D10/clean_data!D$2 -> 1.2600746 | E10: =clean_data!E10/clean_data!E$2 -> 0.9464752 | F10: =clean_data!F10/clean_data!F$2 -> 0.99066111 | G10: =clean_data!G10/clean_data!G$2 -> 1.0258523 | H10: =clean_data!H10/clean_data!H$2 -> 1.0238525 | I10: =clean_data!I10/clean_data!I$2 -> 1.0588235 | ... M10: =clean_data!M10/clean_data!M$2 -> 1.1542974 | N10: =clean_data!O10/clean_data!O$2 -> 0.70060672 | O10: =clean_data!P10/clean_data!P$2 -> 1.0511208
A11: =clean_data!A11 -> 41486 | B11: =clean_data!B11/clean_data!B$2 -> 1.1904911 | C11: =clean_data!C11/clean_data!C$2 -> 1.1111606 | D11: =clean_data!D11/clean_data!D$2 -> 1.230597 | E11: =clean_data!E11/clean_data!E$2 -> 0.9421671 | F11: =clean_data!F11/clean_data!F$2 -> 0.99066111 | G11: =clean_data!G11/clean_data!G$2 -> 1.0365863 | H11: =clean_data!H11/clean_data!H$2 -> 1.0530697 | I11: =clean_data!I11/clean_data!I$2 -> 1.0799736 | ... M11: =clean_data!M11/clean_data!M$2 -> 1.2070882 | N11: =clean_data!O11/clean_data!O$2 -> 0.73942128 | O11: =clean_data!P11/clean_data!P$2 -> 1.060051
A12: =clean_data!A12 -> 41517 | B12: =clean_data!B12/clean_data!B$2 -> 1.1561129 | C12: =clean_data!C12/clean_data!C$2 -> 1.0999421 | D12: =clean_data!D12/clean_data!D$2 -> 1.2022388 | E12: =clean_data!E12/clean_data!E$2 -> 0.9227154 | F12: =clean_data!F12/clean_data!F$2 -> 0.9329512 | G12: =clean_data!G12/clean_data!G$2 -> 1.0300098 | H12: =clean_data!H12/clean_data!H$2 -> 1.039676 | I12: =clean_data!I12/clean_data!I$2 -> 1.0819564 | ... M12: =clean_data!M12/clean_data!M$2 -> 1.1467852 | N12: =clean_data!O12/clean_data!O$2 -> 0.79550404 | O12: =clean_data!P12/clean_data!P$2 -> 1.0560416
A13: =clean_data!A13 -> 41547 | B13: =clean_data!B13/clean_data!B$2 -> 1.1615465 | C13: =clean_data!C13/clean_data!C$2 -> 1.1447285 | D13: =clean_data!D13/clean_data!D$2 -> 1.2764925 | E13: =clean_data!E13/clean_data!E$2 -> 0.9691906 | F13: =clean_data!F13/clean_data!F$2 -> 0.91834289 | G13: =clean_data!G13/clean_data!G$2 -> 1.0401391 | H13: =clean_data!H13/clean_data!H$2 -> 1.0478572 | I13: =clean_data!I13/clean_data!I$2 -> 1.0951751 | ... M13: =clean_data!M13/clean_data!M$2 -> 1.179427 | N13: =clean_data!O13/clean_data!O$2 -> 0.73607654 | O13: =clean_data!P13/clean_data!P$2 -> 1.0552214
... A139: =clean_data!A139 -> 45382 | B139: =clean_data!B139/clean_data!B$2 -> 5.3424242 | C139: =clean_data!C139/clean_data!C$2 -> 3.4134662 | D139: =clean_data!D139/clean_data!D$2 -> 2.8513433 | E139: =clean_data!E139/clean_data!E$2 -> 1.5343342 | F139: =clean_data!F139/clean_data!F$2 -> 1.2573588 | G139: =clean_data!G139/clean_data!G$2 -> 1.2335777 | H139: =clean_data!H139/clean_data!H$2 -> 1.5410072 | I139: =clean_data!I139/clean_data!I$2 -> 1.4844679 | ... M139: =clean_data!M139/clean_data!M$2 -> 4.2191488 | N139: =clean_data!O139/clean_data!O$2 -> 1.4729309 | O139: =clean_data!P139/clean_data!P$2 -> 2.1812466
